<sdf version='1.6'>
  <world name='default'>
    <light name='sun' type='directional'>
      <cast_shadows>1</cast_shadows>
      <pose frame=''>0 0 10 0 -0 0</pose>
      <diffuse>0.8 0.8 0.8 1</diffuse>
      <specular>0.2 0.2 0.2 1</specular>
      <attenuation>
        <range>1000</range>
        <constant>0.9</constant>
        <linear>0.01</linear>
        <quadratic>0.001</quadratic>
      </attenuation>
      <direction>-0.5 0.1 -0.9</direction>
    </light>
    <model name='ground_plane'>
      <static>1</static>
      <link name='link'>
        <collision name='collision'>
          <geometry>
            <plane>
              <normal>0 0 1</normal>
              <size>100 100</size>
            </plane>
          </geometry>
          <surface>
            <contact>
              <collide_bitmask>65535</collide_bitmask>
              <ode/>
            </contact>
            <friction>
              <ode>
                <mu>100</mu>
                <mu2>50</mu2>
              </ode>
              <torsional>
                <ode/>
              </torsional>
            </friction>
            <bounce/>
          </surface>
          <max_contacts>10</max_contacts>
        </collision>
        <visual name='visual'>
          <cast_shadows>0</cast_shadows>
          <geometry>
            <plane>
              <normal>0 0 1</normal>
              <size>100 100</size>
            </plane>
          </geometry>
          <material>
            <script>
              <uri>file://media/materials/scripts/gazebo.material</uri>
              <name>Gazebo/Grey</name>
            </script>
          </material>
        </visual>
        <self_collide>0</self_collide>
        <enable_wind>0</enable_wind>
        <kinematic>0</kinematic>
      </link>
    </model>


    <model name='thirabot'>
            <link name='base_footprint'>
                <pose frame=''>0 0 0 0 -0 0</pose>
                <inertial>
                    <pose frame=''>0 0 0.15 0 -0 0</pose>
                    <mass>100</mass>
                    <inertia>
                        <ixx>2.85417</ixx>
                        <ixy>0</ixy>
                        <ixz>0</ixz>
                        <iyy>8.66667</iyy>
                        <iyz>0</iyz>
                        <izz>10.8542</izz>
                    </inertia>
                </inertial>
                <collision name='base_footprint_fixed_joint_lump__base_link_collision'>
                    <pose frame=''>0 0 0.15 0 -0 0</pose>
                    <geometry>
                        <box>
                            <size>1 0.55 0.2</size>
                        </box>
                    </geometry>
                </collision>
                <visual name='base_footprint_fixed_joint_lump__base_link_visual'>
                    <pose frame=''>0 0 0.15 0 -0 0</pose>
                    <geometry>
                        <box>
                            <size>1 0.55 0.2</size>
                        </box>
                    </geometry>
                    <material>
                        <ambient>0.4 0.4 0.8 1</ambient>
                        <diffuse>0.4 0.4 0.8 1</diffuse>
                        <specular>0.4 0.4 0.8 1</specular>
                    </material>
                </visual>
            </link>

            <link name='l_bogie_suspension'>
                <pose frame=''>-0.25 0.36 0.15 0 -0 0</pose>
                <inertial>
                    <pose frame=''>0 -0.01 0 1.5708 -0 0</pose>
                    <mass>2</mass>
                    <inertia>
                        <ixx>0.00151667</ixx>
                        <ixy>0</ixy>
                        <ixz>0</ixz>
                        <iyy>0.00151667</iyy>
                        <iyz>0</iyz>
                        <izz>0.0009</izz>
                    </inertia>
                </inertial>
                <collision name='l_bogie_suspension_collision'>
                    <pose frame=''>0 -0.01 0 1.5708 -0 0</pose>
                    <geometry>
                        <cylinder>
                            <length>0.08</length>
                            <radius>0.03</radius>
                        </cylinder>
                    </geometry>
                </collision>
                <visual name='l_bogie_suspension_visual'>
                    <pose frame=''>0 -0.01 0 1.5708 -0 0</pose>
                    <geometry>
                        <cylinder>
                            <length>0.08</length>
                            <radius>0.03</radius>
                        </cylinder>
                    </geometry>
                    <material>
                        <ambient>0.6 0.4 0.4 1</ambient>
                        <diffuse>0.6 0.4 0.4 1</diffuse>
                        <specular>0.6 0.4 0.4 1</specular>
                    </material>
                </visual>
            </link>

            <joint name='l_bogie_suspension_joint' type='revolute'>
                <child>l_bogie_suspension</child>
                <parent>base_footprint</parent>
                <axis>
                    <xyz>0 1 0</xyz>
                    <limit>
                        <lower>-3.14159</lower>
                        <upper>3.14159</upper>
                        <effort>1000</effort>
                        <velocity>0.1</velocity>
                    </limit>
                    <dynamics>
                        <spring_reference>0</spring_reference>
                        <spring_stiffness>0</spring_stiffness>
                    </dynamics>
                    <use_parent_model_frame>1</use_parent_model_frame>
                </axis>
            </joint>

            <link name='l_rear_caster_rotate'>
                <pose frame=''>-0.43 0.37 0.15 0 -0 0</pose>
                <inertial>
                    <pose frame=''>0 0 0 0 -0 0</pose>
                    <mass>2</mass>
                    <inertia>
                        <ixx>0.0006</ixx>
                        <ixy>0</ixy>
                        <ixz>0</ixz>
                        <iyy>0.0006</iyy>
                        <iyz>0</iyz>
                        <izz>0.0009</izz>
                    </inertia>
                </inertial>
                <collision name='l_rear_caster_rotate_collision'>
                    <pose frame=''>0 0 0 0 -0 0</pose>
                    <geometry>
                        <cylinder>
                            <length>0.03</length>
                            <radius>0.03</radius>
                        </cylinder>
                    </geometry>
                </collision>
                <visual name='l_rear_caster_rotate_visual'>
                    <pose frame=''>0 0 0 0 -0 0</pose>
                    <geometry>
                        <cylinder>
                            <length>0.03</length>
                            <radius>0.03</radius>
                        </cylinder>
                    </geometry>
                    <material>
                        <ambient>0.3 0.3 0.3 1</ambient>
                        <diffuse>0.3 0.3 0.3 1</diffuse>
                        <specular>0.3 0.3 0.3 1</specular>
                    </material>
                </visual>
            </link>

            <joint name='l_rear_caster_rotate_joint' type='revolute'>
                <child>l_rear_caster_rotate</child>
                <parent>l_bogie_suspension</parent>
                <axis>
                    <xyz>0 0 1</xyz>
                    <limit>
                        <lower>-1e+16</lower>
                        <upper>1e+16</upper>
                    </limit>
                    <dynamics>
                        <spring_reference>0</spring_reference>
                        <spring_stiffness>0</spring_stiffness>
                    </dynamics>
                    <use_parent_model_frame>1</use_parent_model_frame>
                </axis>
            </joint>

            <link name='l_rear_caster_wheel'>
                <pose frame=''>-0.445 0.37 0.06 0 -0 0</pose>
                <inertial>
                    <pose frame=''>0 0 0 1.5708 -0 0</pose>
                    <mass>2</mass>
                    <inertia>
                        <ixx>0.00206667</ixx>
                        <ixy>0</ixy>
                        <ixz>0</ixz>
                        <iyy>0.00206667</iyy>
                        <iyz>0</iyz>
                        <izz>0.0036</izz>
                    </inertia>
                </inertial>
                <collision name='l_rear_caster_wheel_collision'>
                    <pose frame=''>0 0 0 1.5708 -0 0</pose>
                    <geometry>
                        <cylinder>
                            <length>0.04</length>
                            <radius>0.06</radius>
                        </cylinder>
                    </geometry>
                    <surface>
                        <contact>
                            <ode>
                                <kp>1e+07</kp>
                                <kd>1</kd>
                                <min_depth>0.0</min_depth>
                            </ode>
                        </contact>
                        <friction>
                            <ode>
                                <mu2>1</mu2>
                            </ode>
                        </friction>
                    </surface>
                </collision>
                <visual name='l_rear_caster_wheel_visual'>
                    <pose frame=''>0 0 0 1.5708 -0 0</pose>
                    <geometry>
                        <cylinder>
                            <length>0.04</length>
                            <radius>0.06</radius>
                        </cylinder>
                    </geometry>
                    <material>
                        <ambient>0.1 0.1 0.1 1</ambient>
                        <diffuse>0.1 0.1 0.1 1</diffuse>
                        <specular>0.1 0.1 0.1 1</specular>
                    </material>
                </visual>
                <gravity>1</gravity>
                <velocity_decay/>
            </link>

            <joint name='l_rear_caster_wheel_joint' type='revolute'>
                <child>l_rear_caster_wheel</child>
                <parent>l_rear_caster_rotate</parent>
                <axis>
                    <xyz>0 1 0</xyz>
                    <limit>
                        <lower>-1e+16</lower>
                        <upper>1e+16</upper>
                    </limit>
                    <dynamics>
                        <spring_reference>0</spring_reference>
                        <spring_stiffness>0</spring_stiffness>
                    </dynamics>
                    <use_parent_model_frame>1</use_parent_model_frame>
                </axis>
            </joint>

            <link name='l_wheel'>
                <pose frame=''>0 0.37 0.1 0 -0 0</pose>
                <inertial>
                    <pose frame=''>0 0 0 1.5708 -0 0</pose>
                    <mass>2</mass>
                    <inertia>
                        <ixx>0.2</ixx>
                        <ixy>0</ixy>
                        <ixz>0</ixz>
                        <iyy>0.2</iyy>
                        <iyz>0</iyz>
                        <izz>0.2</izz>
                    </inertia>
                </inertial>
                <collision name='l_wheel_collision'>
                    <pose frame=''>0 0 0 1.5708 -0 0</pose>
                    <geometry>
                        <cylinder>
                            <length>0.06</length>
                            <radius>0.1</radius>
                        </cylinder>
                    </geometry>
                    <surface>
                        <contact>
                            <ode>
                                <kp>1e+07</kp>
                                <kd>1</kd>
                                <min_depth>0.0</min_depth>
                            </ode>
                        </contact>
                        <friction>
                            <ode>
                                <mu2>200</mu2>
                            </ode>
                        </friction>
                    </surface>
                </collision>
                <visual name='l_wheel_visual'>
                    <pose frame=''>0 0 0 1.5708 -0 0</pose>
                    <geometry>
                        <cylinder>
                            <length>0.06</length>
                            <radius>0.1</radius>
                        </cylinder>
                    </geometry>
                    <material>
                        <ambient>0.3 0.3 0.3 1</ambient>
                        <diffuse>0.3 0.3 0.3 1</diffuse>
                        <specular>0.3 0.3 0.3 1</specular>
                    </material>
                </visual>
                <gravity>1</gravity>
                <velocity_decay/>
            </link>
            <joint name='l_wheel_joint' type='revolute'>
                <child>l_wheel</child>
                <parent>l_bogie_suspension</parent>
                <axis>
                    <xyz>0 1 0</xyz>
                    <limit>
                        <lower>-1e+16</lower>
                        <upper>1e+16</upper>
                    </limit>
                    <dynamics>
                        <spring_reference>0</spring_reference>
                        <spring_stiffness>0</spring_stiffness>
                    </dynamics>
                    <use_parent_model_frame>1</use_parent_model_frame>
                </axis>
            </joint>
            <link name='l_front_caster_rotate'>
                <pose frame=''>0.43 0.37 0.15 0 -0 0</pose>
                <inertial>
                    <pose frame=''>0 0 0 0 -0 0</pose>
                    <mass>2</mass>
                    <inertia>
                        <ixx>0.0006</ixx>
                        <ixy>0</ixy>
                        <ixz>0</ixz>
                        <iyy>0.0006</iyy>
                        <iyz>0</iyz>
                        <izz>0.0009</izz>
                    </inertia>
                </inertial>
                <collision name='l_front_caster_rotate_collision'>
                    <pose frame=''>0 0 0 0 -0 0</pose>
                    <geometry>
                        <cylinder>
                            <length>0.03</length>
                            <radius>0.03</radius>
                        </cylinder>
                    </geometry>
                </collision>
                <visual name='l_front_caster_rotate_visual'>
                    <pose frame=''>0 0 0 0 -0 0</pose>
                    <geometry>
                        <cylinder>
                            <length>0.03</length>
                            <radius>0.03</radius>
                        </cylinder>
                    </geometry>
                    <material>
                        <ambient>0.3 0.3 0.3 1</ambient>
                        <diffuse>0.3 0.3 0.3 1</diffuse>
                        <specular>0.3 0.3 0.3 1</specular>
                    </material>
                </visual>
            </link>
            <joint name='l_front_caster_rotate_joint' type='revolute'>
                <child>l_front_caster_rotate</child>
                <parent>base_footprint</parent>
                <axis>
                    <xyz>0 0 1</xyz>
                    <limit>
                        <lower>-1e+16</lower>
                        <upper>1e+16</upper>
                    </limit>
                    <dynamics>
                        <spring_reference>0</spring_reference>
                        <spring_stiffness>0</spring_stiffness>
                    </dynamics>
                    <use_parent_model_frame>1</use_parent_model_frame>
                </axis>
            </joint>
            <link name='l_front_caster_wheel'>
                <pose frame=''>0.415 0.37 0.06 0 -0 0</pose>
                <inertial>
                    <pose frame=''>0 0 0 1.5708 -0 0</pose>
                    <mass>2</mass>
                    <inertia>
                        <ixx>0.00206667</ixx>
                        <ixy>0</ixy>
                        <ixz>0</ixz>
                        <iyy>0.00206667</iyy>
                        <iyz>0</iyz>
                        <izz>0.0036</izz>
                    </inertia>
                </inertial>
                <collision name='l_front_caster_wheel_collision'>
                    <pose frame=''>0 0 0 1.5708 -0 0</pose>
                    <geometry>
                        <cylinder>
                            <length>0.04</length>
                            <radius>0.06</radius>
                        </cylinder>
                    </geometry>
                    <surface>
                        <contact>
                            <ode>
                                <kp>1e+07</kp>
                                <kd>1</kd>
                                <min_depth>0.0</min_depth>
                            </ode>
                        </contact>
                        <friction>
                            <ode>
                                <mu2>1</mu2>
                            </ode>
                        </friction>
                    </surface>
                </collision>
                <visual name='l_front_caster_wheel_visual'>
                    <pose frame=''>0 0 0 1.5708 -0 0</pose>
                    <geometry>
                        <cylinder>
                            <length>0.04</length>
                            <radius>0.06</radius>
                        </cylinder>
                    </geometry>
                    <material>
                        <ambient>0.1 0.1 0.1 1</ambient>
                        <diffuse>0.1 0.1 0.1 1</diffuse>
                        <specular>0.1 0.1 0.1 1</specular>
                    </material>
                </visual>
                <gravity>1</gravity>
                <velocity_decay/>
            </link>
            <joint name='l_front_caster_wheel_joint' type='revolute'>
                <child>l_front_caster_wheel</child>
                <parent>l_front_caster_rotate</parent>
                <axis>
                    <xyz>0 1 0</xyz>
                    <limit>
                        <lower>-1e+16</lower>
                        <upper>1e+16</upper>
                    </limit>
                    <dynamics>
                        <spring_reference>0</spring_reference>
                        <spring_stiffness>0</spring_stiffness>
                    </dynamics>
                    <use_parent_model_frame>1</use_parent_model_frame>
                </axis>
            </joint>
            <link name='r_bogie_suspension'>
                <pose frame=''>-0.25 -0.36 0.15 0 -0 0</pose>
                <inertial>
                    <pose frame=''>0 0.01 0 1.5708 -0 0</pose>
                    <mass>2</mass>
                    <inertia>
                        <ixx>0.00151667</ixx>
                        <ixy>0</ixy>
                        <ixz>0</ixz>
                        <iyy>0.00151667</iyy>
                        <iyz>0</iyz>
                        <izz>0.0009</izz>
                    </inertia>
                </inertial>
                <collision name='r_bogie_suspension_collision'>
                    <pose frame=''>0 0.01 0 1.5708 -0 0</pose>
                    <geometry>
                        <cylinder>
                            <length>0.08</length>
                            <radius>0.03</radius>
                        </cylinder>
                    </geometry>
                </collision>
                <visual name='r_bogie_suspension_visual'>
                    <pose frame=''>0 0.01 0 1.5708 -0 0</pose>
                    <geometry>
                        <cylinder>
                            <length>0.08</length>
                            <radius>0.03</radius>
                        </cylinder>
                    </geometry>
                </visual>
            </link>
            <joint name='r_bogie_suspension_joint' type='revolute'>
                <child>r_bogie_suspension</child>
                <parent>base_footprint</parent>
                <axis>
                    <xyz>0 1 0</xyz>
                    <limit>
                        <lower>-3.14159</lower>
                        <upper>3.14159</upper>
                        <effort>1000</effort>
                        <velocity>0.1</velocity>
                    </limit>
                    <dynamics>
                        <spring_reference>0</spring_reference>
                        <spring_stiffness>0</spring_stiffness>
                    </dynamics>
                    <use_parent_model_frame>1</use_parent_model_frame>
                </axis>
            </joint>
            <link name='r_rear_caster_rotate'>
                <pose frame=''>-0.43 -0.37 0.15 0 -0 0</pose>
                <inertial>
                    <pose frame=''>0 0 0 0 -0 0</pose>
                    <mass>2</mass>
                    <inertia>
                        <ixx>0.0006</ixx>
                        <ixy>0</ixy>
                        <ixz>0</ixz>
                        <iyy>0.0006</iyy>
                        <iyz>0</iyz>
                        <izz>0.0009</izz>
                    </inertia>
                </inertial>
                <collision name='r_rear_caster_rotate_collision'>
                    <pose frame=''>0 0 0 0 -0 0</pose>
                    <geometry>
                        <cylinder>
                            <length>0.03</length>
                            <radius>0.03</radius>
                        </cylinder>
                    </geometry>
                </collision>
                <visual name='r_rear_caster_rotate_visual'>
                    <pose frame=''>0 0 0 0 -0 0</pose>
                    <geometry>
                        <cylinder>
                            <length>0.03</length>
                            <radius>0.03</radius>
                        </cylinder>
                    </geometry>
                </visual>
            </link>
            <joint name='r_rear_caster_rotate_joint' type='revolute'>
                <child>r_rear_caster_rotate</child>
                <parent>r_bogie_suspension</parent>
                <axis>
                    <xyz>0 0 1</xyz>
                    <limit>
                        <lower>-1e+16</lower>
                        <upper>1e+16</upper>
                    </limit>
                    <dynamics>
                        <spring_reference>0</spring_reference>
                        <spring_stiffness>0</spring_stiffness>
                    </dynamics>
                    <use_parent_model_frame>1</use_parent_model_frame>
                </axis>
            </joint>
            <link name='r_rear_caster_wheel'>
                <pose frame=''>-0.445 -0.37 0.06 0 -0 0</pose>
                <inertial>
                    <pose frame=''>0 0 0 1.5708 -0 0</pose>
                    <mass>2</mass>
                    <inertia>
                        <ixx>0.00206667</ixx>
                        <ixy>0</ixy>
                        <ixz>0</ixz>
                        <iyy>0.00206667</iyy>
                        <iyz>0</iyz>
                        <izz>0.0036</izz>
                    </inertia>
                </inertial>
                <collision name='r_rear_caster_wheel_collision'>
                    <pose frame=''>0 0 0 1.5708 -0 0</pose>
                    <geometry>
                        <cylinder>
                            <length>0.04</length>
                            <radius>0.06</radius>
                        </cylinder>
                    </geometry>
                    <surface>
                        <contact>
                            <ode>
                                <kp>1e+07</kp>
                                <kd>1</kd>
                                <min_depth>0.0</min_depth>
                            </ode>
                        </contact>
                        <friction>
                            <ode>
                                <mu2>1</mu2>
                            </ode>
                        </friction>
                    </surface>
                </collision>
                <visual name='r_rear_caster_wheel_visual'>
                    <pose frame=''>0 0 0 1.5708 -0 0</pose>
                    <geometry>
                        <cylinder>
                            <length>0.04</length>
                            <radius>0.06</radius>
                        </cylinder>
                    </geometry>

                </visual>
                <gravity>1</gravity>
                <velocity_decay/>
            </link>
            <joint name='r_rear_caster_wheel_joint' type='revolute'>
                <child>r_rear_caster_wheel</child>
                <parent>r_rear_caster_rotate</parent>
                <axis>
                    <xyz>0 1 0</xyz>
                    <limit>
                        <lower>-1e+16</lower>
                        <upper>1e+16</upper>
                    </limit>
                    <dynamics>
                        <spring_reference>0</spring_reference>
                        <spring_stiffness>0</spring_stiffness>
                    </dynamics>
                    <use_parent_model_frame>1</use_parent_model_frame>
                </axis>
            </joint>
            <link name='r_wheel'>
                <pose frame=''>0 -0.37 0.1 0 -0 0</pose>
                <inertial>
                    <pose frame=''>0 0 0 1.5708 -0 0</pose>
                    <mass>2</mass>
                    <inertia>
                        <ixx>0.2</ixx>
                        <ixy>0</ixy>
                        <ixz>0</ixz>
                        <iyy>0.2</iyy>
                        <iyz>0</iyz>
                        <izz>0.2</izz>
                    </inertia>
                </inertial>
                <collision name='r_wheel_collision'>
                    <pose frame=''>0 0 0 1.5708 -0 0</pose>
                    <geometry>
                        <cylinder>
                            <length>0.06</length>
                            <radius>0.1</radius>
                        </cylinder>
                    </geometry>
                    <surface>
                        <contact>
                            <ode>
                                <kp>1e+07</kp>
                                <kd>1</kd>
                                <min_depth>0.0</min_depth>
                            </ode>
                        </contact>
                        <friction>
                            <ode>
                                <mu2>200</mu2>
                            </ode>
                        </friction>
                    </surface>
                </collision>
                <visual name='r_wheel_visual'>
                    <pose frame=''>0 0 0 1.5708 -0 0</pose>
                    <geometry>
                        <cylinder>
                            <length>0.06</length>
                            <radius>0.1</radius>
                        </cylinder>
                    </geometry>

                </visual>
                <gravity>1</gravity>
                <velocity_decay/>
            </link>
            <joint name='r_wheel_joint' type='revolute'>
                <child>r_wheel</child>
                <parent>r_bogie_suspension</parent>
                <axis>
                    <xyz>0 1 0</xyz>
                    <limit>
                        <lower>-1e+16</lower>
                        <upper>1e+16</upper>
                    </limit>
                    <dynamics>
                        <spring_reference>0</spring_reference>
                        <spring_stiffness>0</spring_stiffness>
                    </dynamics>
                    <use_parent_model_frame>1</use_parent_model_frame>
                </axis>
            </joint>
            <link name='r_front_caster_rotate'>
                <pose frame=''>0.43 -0.37 0.15 0 -0 0</pose>
                <inertial>
                    <pose frame=''>0 0 0 0 -0 0</pose>
                    <mass>2</mass>
                    <inertia>
                        <ixx>0.0006</ixx>
                        <ixy>0</ixy>
                        <ixz>0</ixz>
                        <iyy>0.0006</iyy>
                        <iyz>0</iyz>
                        <izz>0.0009</izz>
                    </inertia>
                </inertial>
                <collision name='r_front_caster_rotate_collision'>
                    <pose frame=''>0 0 0 0 -0 0</pose>
                    <geometry>
                        <cylinder>
                            <length>0.03</length>
                            <radius>0.03</radius>
                        </cylinder>
                    </geometry>
                </collision>
                <visual name='r_front_caster_rotate_visual'>
                    <pose frame=''>0 0 0 0 -0 0</pose>
                    <geometry>
                        <cylinder>
                            <length>0.03</length>
                            <radius>0.03</radius>
                        </cylinder>
                    </geometry>
                </visual>
            </link>
            <joint name='r_front_caster_rotate_joint' type='revolute'>
                <child>r_front_caster_rotate</child>
                <parent>base_footprint</parent>
                <axis>
                    <xyz>0 0 1</xyz>
                    <limit>
                        <lower>-1e+16</lower>
                        <upper>1e+16</upper>
                    </limit>
                    <dynamics>
                        <spring_reference>0</spring_reference>
                        <spring_stiffness>0</spring_stiffness>
                    </dynamics>
                    <use_parent_model_frame>1</use_parent_model_frame>
                </axis>
            </joint>
            <link name='r_front_caster_wheel'>
                <pose frame=''>0.415 -0.37 0.06 0 -0 0</pose>
                <inertial>
                    <pose frame=''>0 0 0 1.5708 -0 0</pose>
                    <mass>2</mass>
                    <inertia>
                        <ixx>0.00206667</ixx>
                        <ixy>0</ixy>
                        <ixz>0</ixz>
                        <iyy>0.00206667</iyy>
                        <iyz>0</iyz>
                        <izz>0.0036</izz>
                    </inertia>
                </inertial>
                <collision name='r_front_caster_wheel_collision'>
                    <pose frame=''>0 0 0 1.5708 -0 0</pose>
                    <geometry>
                        <cylinder>
                            <length>0.04</length>
                            <radius>0.06</radius>
                        </cylinder>
                    </geometry>
                    <surface>
                        <contact>
                            <ode>
                                <kp>1e+07</kp>
                                <kd>1</kd>
                                <min_depth>0.0</min_depth>
                            </ode>
                        </contact>
                        <friction>
                            <ode>
                                <mu2>1</mu2>
                            </ode>
                        </friction>
                    </surface>
                </collision>
                <visual name='r_front_caster_wheel_visual'>
                    <pose frame=''>0 0 0 1.5708 -0 0</pose>
                    <geometry>
                        <cylinder>
                            <length>0.04</length>
                            <radius>0.06</radius>
                        </cylinder>
                    </geometry>

                </visual>
                <gravity>1</gravity>
                <velocity_decay/>
            </link>
            <joint name='r_front_caster_wheel_joint' type='revolute'>
                <child>r_front_caster_wheel</child>
                <parent>r_front_caster_rotate</parent>
                <axis>
                    <xyz>0 1 0</xyz>
                    <limit>
                        <lower>-1e+16</lower>
                        <upper>1e+16</upper>
                    </limit>
                    <dynamics>
                        <spring_reference>0</spring_reference>
                        <spring_stiffness>0</spring_stiffness>
                    </dynamics>
                    <use_parent_model_frame>1</use_parent_model_frame>
                </axis>
            </joint>
            <static>0</static>

            <!-- <plugin name="differential_drive_controller" filename="libgazebo_ros_diff_drive.so">
              <leftJoint>l_wheel_joint</leftJoint>
              <rightJoint>r_wheel_joint</rightJoint>
              <wheelSeparation>0.5380</wheelSeparation>
              <wheelDiameter>0.2410</wheelDiameter>
            </plugin> -->

        </model>



    <gravity>0 0 -9.8</gravity>
    <magnetic_field>6e-06 2.3e-05 -4.2e-05</magnetic_field>
    <atmosphere type='adiabatic'/>
    <physics name='default_physics' default='0' type='ode'>
      <max_step_size>0.001</max_step_size>
      <real_time_factor>1</real_time_factor>
      <real_time_update_rate>1000</real_time_update_rate>
    </physics>
    <scene>
      <ambient>0.4 0.4 0.4 1</ambient>
      <background>0.7 0.7 0.7 1</background>
      <shadows>1</shadows>
    </scene>
    <wind/>
    <spherical_coordinates>
      <surface_model>EARTH_WGS84</surface_model>
      <latitude_deg>0</latitude_deg>
      <longitude_deg>0</longitude_deg>
      <elevation>0</elevation>
      <heading_deg>0</heading_deg>
    </spherical_coordinates>
    <state world_name='default'>
      <sim_time>16 392000000</sim_time>
      <real_time>16 435015470</real_time>
      <wall_time>1589330273 882054525</wall_time>
      <iterations>16392</iterations>
      <model name='ground_plane'>
        <pose frame=''>0 0 0 0 -0 0</pose>
        <scale>1 1 1</scale>
        <link name='link'>
          <pose frame=''>0 0 0 0 -0 0</pose>
          <velocity>0 0 0 0 -0 0</velocity>
          <acceleration>0 0 0 0 -0 0</acceleration>
          <wrench>0 0 0 0 -0 0</wrench>
        </link>
      </model>
      <light name='sun'>
        <pose frame=''>0 0 10 0 -0 0</pose>
      </light>
    </state>
    <gui fullscreen='0'>
      <camera name='user_camera'>
        <pose frame=''>5 -5 2 0 0.275643 2.35619</pose>
        <view_controller>orbit</view_controller>
        <projection_type>perspective</projection_type>
      </camera>
    </gui>
  </world>
</sdf>
